Workbook

Sheet Bug Report
A1: Bug Report — Event Management System
A2: Legend: fill in the yellow cells below. One row per bug. Use the dropdowns for Severity and Module.
A4: Tester name: | B4: Nafeel Sarook
A5: Date: | B5: 10.10.2026
A6: Build / URL tested: | B6: https://qa.caprconuat.xyz/events
A7: Browser / device: | B7: Microsoft Edge
A9: Bug # | B9: Title | C9: Severity | D9: Module / Page | E9: Environment (role) | F9: Steps to Reproduce | G9: Expected Result | H9: Actual Result | I9: Screenshots / Evidence | J9: Additional Notes | K9: Status
A10: 1 | B10: Any user can register as an admin | C10: Critical | D10: Admin Portal → User Registration | E10: Guest (unauthenticated) | F10: 1. Go to /register 2. Select "Admin" in Register As 3. Submit 4. Log in | G10: Registration should ignore/reject a self-selected admin role | H10: Account is created with role=admin and has full admin access | I10: (attach screenshot) | J10: Mass-assignment via $request->all() in RegisteredUserController | K10: Open
A11: 1 - Event Listing | B11: The events page lists all events in a responsive card grid, 6 per page, with pagination. | C11: Medium | D11: Other | E11: Guest, User | F11: 1. Open with public Portal. 2. Count the event cards displayed on the first page. 3. Check whether exactly 6 events are displayed. 4. Look for pagination controls, such as Next, page numbers, or Previous | G11: The page should display six event cards per page, with pagination to navigate between pages | H11: The page displays six event cards per page, with pagination to navigate between pages | J11: URD Section 3.1 - Event page list successfully visible with pagination. | K11: Fixed
A12: 2 - Event Listing | B12: Each event card shows: title, venue, date/time, a short description, price (or 'Free' if price is 0), and an 'Upcoming' or 'Past' status badge based on the event date. | C12: Medium | D12: Other | E12: User | F12: 1. Open the public Event Listing page. 2. Select an event card and check whether it displays: - Event title - Venue - Date and time - Short description - Price, or 'Free' if the price is 0 - Status badge: Upcoming or Past 3. Repeat for several event cards, including at least one past event and one upcoming event. 4. Compare each event's status with its actual date and time. 5. If a free event is available, verify that its price displays as 'Free', not 0. | G12: All required details should be visible on each card, and the status badge correctly reflects whether the event is upcoming or past. | H12: All required details are visible on each card, and the status badge correctly reflects whether the event is upcoming or past. | J12: URD Section 3.1 - required details are visible on each card, and the status badge correctly reflects | K12: Fixed
A13: 3 - Event Listing | B13: Each event card shows: title, venue, date/time, a short description, price (or 'Free' if price is 0), and an 'Upcoming' or 'Past' status badge based on the event date. | C13: Medium | D13: Other | E13: Guest | F13: 1. Open the public Event Listing page withoud login. 2. Select an event card and check whether it displays: - Event title - Venue - Date and time - Short description - Price, or 'Free' if the price is 0 - Status badge: Upcoming or Past 3. Repeat for several event cards, including at least one past event and one upcoming event. 4. Compare each event's status with its actual date and time. 5. If a free event is available, verify that its price displays as 'Free', not 0. | G13: Guests should see a prompt to log in or register instead. | H13: As a guest user can see all the relevent detais but the nubmer of seats and book now options are not visible | J13: URD Section 3.1 - required details are visible on each card, and the status badge correctly reflects related to the user role | K13: Fixed
A14: 4 - Event Listing | B14: Cards must be evenly aligned in the grid at every screen width (mobile, tablet, desktop) with no overlapping or visually offset cards. | C14: Cosmetic | D14: Other | E14: User | F14: 1. Open with public Portal. 2. Navigate to the event listing page. 3. Observe all six event cards. 4. Compare the fifth card's alignment with the others. | G14: All event cards should be evenly aligned in the grid without unexpected offsets. | H14: The fifth event card appears misaligned compared with the other event cards. | I14: https://drive.google.com/file/d/1ADx2xLlUePRP9WOtXdyIAy8P6p5V-b-L/view?usp=sharing | J14: URD Section 3.1 - Event cards must be evenly aligned at every screen width. | K14: Open
A15: 5 - Event Listing | B15: Only events that are genuinely relevant to browse/book should be presented as bookable; past events should be clearly distinguishable from upcoming ones | C15: High | D15: Public Portal → Event Booking | E15: User | F15: 1. Log in with a test user account. 2. Open an event whose date and time are in the past. 3. Enter a valid ticket quantity. 4. Click Book Now. 5. Observe the result | G15: The system should prevent bookings for past events and display a clear validation message. | H15: All three tested user accounts were able to book tickets for past events. | I15: https://drive.google.com/file/d/1T3t44wPk7ds7Ql9Y_XztFsM_na9WES2t/view?usp=sharing | J15: URD Sections 3.1 and 3.4. Verify whether the resulting bookings appear in My Bookings and the Admin Portal. | K15: Open
A16: 6 - Event Listing | B16: Only events that are genuinely relevant to browse/book should be presented as bookable; past events should be clearly distinguishable from upcoming ones | C16: High | D16: Public Portal → Event Booking | E16: Guest | F16: 1. Open an eventas a guest 2. Try to enter valid ticket QTY 3. Try to Click Book Now. 4. Observe the result | G16: The system should not prevent ticket quantity and bookings for guest user | H16: As a guest user can see a prompt to log in , create an account instead of ticket qty and book now | K16: Fixed
A17: 7 - Search | B17: Users can search events by title from the search box on the events page | C17: High | D17: Other | E17: User | F17: 1. Log in with puplic portal account 2. Open the public Event Listing page. 3. Choose an event and note its exact title. 4. Enter the complete title into the search box. 5. Click Search | G17: The user should find out the search box | H17: Successfully find the search box in the event page | J17: URD Section 3.2 - find the search box in the event page | K17: Fixed
A18: 8 - Search | B18: Search should match partial and case-insensitive input (e.g. searching “tech” should find “Colombo Tech Summit”). | C18: Medium | D18: Other | E18: User | F18: 1. Log in with puplic portal account. 2. Open the events page. 3. Enter only part of an existing event title in the search box. 4. Observe the search results. 5. Repeat with the other two accounts. | G18: Search should return matching events when users enter only part of an event title, regardless of letter casing. | H18: Search does not filter correctly using partial title input; users must type the entire event title to find the event. | I18: https://drive.google.com/file/d/1OY6vqWeoj4bla9fDSixwHh1kpjBofotg/view?usp=sharing | J18: URD Section 3.2 - Search must support partial and case-insensitive matching. | K18: Open
A19: 9 - Search | B19: The search term should remain applied when navigating between pages of results. | C19: Medium | D19: Other | E19: User | F19: 1. Log in with puplic portal account. 2. Open the events page. 3. Enter a search term that returns multiple results across pages. 4. Navigate to the next page of results. 5. Observe the search box and displayed events | G19: The search term should remain applied, and the next page should display results matching the same search term. | H19: The search term is not retained when navigating between result pages. | I19: https://drive.google.com/file/d/1IcKlDHdAcFBCqGz7gLmzff884ycJK_0k/view?usp=sharing | J19: URD Section 3.2 - Search term must remain applied during pagination. | K19: Open
A20: 10 - Search | B20: A clear 'no events found' message should appear when a search has no matches. | C20: Low | D20: Public Portal → Event Browsing | E20: User | F20: 1. Login with public portal 2. Open the Event Listing page. 3. Enter a search term that does not match any event title (e.g.,incorrect event). 4. Click Search. 5. Observe the results area. | G20: A clear 'No events found for your search' message should appear when the search returns no matching events. | H20: No events found for your search' message is displayed. | J20: URD Section 3.3 - 'No events found for your search' message is displayed. | K20: Fixed
A21: 11 - Search | B21: Clearing the search field does not automatically refresh the event list | C21: Low | D21: Other | E21: User | F21: 1. Log in with puplic portal account. 2. Open the events page. 3. Enter a search term and click Search. 4. Clear the search field. 5. Observe whether the full event list is restored without clicking Search. | G21: Ideally, clearing the search field should reset the filter and restore the full event list. | H21: Clearing the search field does not automatically refresh the event list; the user must click Search. | I21: https://drive.google.com/file/d/1_nweVo4H3f_P88Cwq8Cc-UlI55C_GNHt/view?usp=sharing | J21: The URD does not explicitly require automatic refresh on clearing the field. Confirm whether this is intended behavior before including it in the final report. | K21: Open
A22: 12 - Event details | B22: The event details page shows full event information: title, venue, date/time, full description, price, and remaining capacity. | C22: Medium | D22: Other | E22: User | F22: 1. Open the Public Portal. 2. Select an event with existing bookings. 3. Open its Event Details page. 4. Check the displayed seat capacity. 5. Compare it with the event's total capacity and confirmed tickets booked. | G22: The page should display the remaining capacity, calculated as total capacity minus tickets already booked. | H22: The page displays the event's total seat capacity instead of the remaining capacity. | I22: https://drive.google.com/file/d/124Wqb2NyF_i_k0OiJ__LnioXR9K_ctt9/view?usp=sharing | J22: URD Section 3.3 — Event Details must show remaining capacity. | K22: Open
A23: 13 - Event details | B23: Logged-in users see a booking form (ticket quantity + “Book Now”); guests see a prompt to log in or register instead. | C23: Medium | D23: Other | E23: Guest and logged-in user | F23: 1. Open the Public Portal. 2. Log out and open an event's details page. 3. Check the booking section. 4. Log in with a valid customer account. 5. Open an upcoming event's details page. 6. Check the booking section again. | G23: Guests should see a prompt to log in or register. Logged-in customers should see the ticket quantity field and 'Book Now' button. | H23: As a guest user can see a prompt to log in , create an account instead of ticket qty and book now | K23: Fixed
A24: 14 - Booking | B24: A logged-in user can book 1 or more tickets for an upcoming event. | C24: Medium | D24: Public Portal → Event Booking | E24: Loged user | F24: 1. Log in as a user. 2. Open an upcoming event 3. Enter a valid quantity (e.g., 1). 4. Click 'Book Now'. 5. Observe the results | G24: The system should successfully create the booking for the requested quantity. | H24: The system successfully create the booking for the requested quantity. | K24: Fixed
A25: 15 - Booking | B25: The booking quantity must be a positive whole number; zero, negative, decimal, or blank quantities must be rejected with a validation message | C25: Medium | D25: Public Portal → Event Booking | E25: Loged user | F25: 1. Log in as a user. 2. Open an existing event. 3. Enter 0, a negative number, a decimal, or leave the quantity blank. 4. Click 'Book Now'. | G25: The system should reject invalid quantities and display a validation message. | H25: The system successfully reject invalid quantities and display a validation message. | K25: Fixed
A26: 16 - Booking | B26: Booking quantity exceeds remaining event capacity | C26: High | D26: Public Portal → Event Booking | E26: Loged user | F26: 1. Log in as a user. 2. Open an event with known remaining capacity. 3. Enter a quantity greater than the remaining capacity. 4. Click 'Book Now'. | G26: The system should reject the booking and prevent the event capacity from being exceeded | H26: The system does not reject the booking; it was accepted as a booking. | I26: https://drive.google.com/file/d/1fesP13qzkTvgheRwW_TQDFJD2oYsinP4/view?usp=sharing | K26: Open
A27: 17 - Booking | B27: Incorrect total booking price calculation | C27: High | D27: Public Portal → Event Booking | E27: Loged user | F27: 1. Log in as a user. 2. Open an upcoming event. 3. Note the ticket price. 4. Enter a valid quantity greater than 1. 5. Submit the booking and check the total charged. | G27: The total price should equal ticket price × quantity. | H27: Incorrect total price displayed | I27: https://drive.google.com/file/d/1BE61S6e4PfdYqeiAaMaD2dX5ReIAKDbI/view?usp=sharing | K27: Open
A28: 18 - Booking | B28: A single click/submit of Book Now must create exactly one booking - rapid repeated clicks must not create duplicate bookings | C28: High | D28: Public Portal → Event Booking | E28: Loged user | F28: 1. Log in as a user. 2. Open an existing event. 3. Enter a valid quantity. 4. Click 'Book Now' repeatedly in quick succession. 5. Check 'My Bookings' for duplicate records. | G28: One submission should create exactly one booking. | H28: One submission create exactly one booking. | K28: Fixed
A29: 19 - Booking | B29: On success, the user is redirected to “My Bookings” with a clear confirmation message, and the new booking appears in the list immediately. | C29: Medium | D29: Public Portal → Event Booking | E29: Loged user | F29: 1. Log in as a customer. 2. Complete a valid booking. 3. Observe the destination page and confirmation message. 4. Check whether the new booking appears immediately. | G29: The system should redirect to 'My Bookings', display a clear confirmation message, and show the new booking immediately. | H29: The system redirected to my booking and displayed confirmation message, but does not redirect to new booking | I29: https://drive.google.com/file/d/1GVChaUS0jL8pG8vrhcXPd11b0ccHwXDH/view?usp=sharing | K29: Open
A30: 20 - Booking | B30: Booking or My Bookings page responds too slowly | C30: Medium | D30: Public Portal → Event Booking | E30: Loged user | F30: 1. Login as a user 2. Complete a valid booking and measure the response time. 3. Open 'My Bookings' and measure its loading time. 4. Repeat the measurement to confirm the issue. | G30: Booking and viewing bookings should respond promptly without long waits. | H30: The booking operation and My Bookings page takes an unusually long time to respond. | I30: https://drive.google.com/file/d/1tOZht1ZpNwo7xLEMDQXpShiA-K5ZPGH9/view?usp=sharing | K30: Open
A31: 21 - MyBooking | B31: A logged-in user can view all of their own bookings: event, venue, date, quantity, total price, and status | C31: Medium | D31: Other | E31: Loged user | F31: 1. Log in as a user with existing bookings. 2. Open My Bookings. 3. Inspect the details displayed for each booking. | G31: Each booking should display event, venue, date/time, quantity, total price, and status. | H31: Successfully displayed each details of the booking | K31: Fixed
A32: 22 - MyBooking | B32: Verify that My Bookings summary tiles display total bookings, total tickets, and total amount spent accurately. | C32: Medium | D32: Other | E32: Loged user | F32: 1. Log in as a user 2. Redirect to My Bookings. 3. Verify the Summary tiles | G32: Summary values should match the sum of the user's listed bookings. | H32: All relevant summary details are displayed successfully. | K32: Fixed
A33: 23 - MyBooking | B33: Available slots are not displayed in the Admin Upcoming Events section after booking cancellation | C33: Medium | D33: Other | E33: Loged user and Admin | F33: 1. Log in as a user. 2. Open My Bookings. 3. Cancel an existing booking. 4. Log in to the Admin Portal. 5. Open the Upcoming Events section and check the event's available slots. | G33: Cancelled tickets should be released, and the updated available capacity should be reflected wherever capacity information is displayed. The cancelled booking should not count toward active/confirmed bookings or admin totals. | H33: The customer can cancel their own booking, but the Admin Portal's Upcoming Events section does not show the available slots after cancellation. | I33: https://drive.google.com/file/d/1U_J4edQ2ECShJokZXT2TPhsvIZ0NOAUd/view?usp=sharing | K33: Open
A34: 24 - MyBooking | B34: A user must not be able to view or cancel another user's booking. | C34: Medium | D34: Other | E34: Loged user | F34: 1. Log in to a customer account. 2. Open My Bookings. 3. View the displayed bookings. 4. Check whether the user can view or edit bookings belonging to another account. | G34: Users must be able to view, edit, or cancel only their own bookings. Access to another user's booking must be denied. | H34: The logged-in user can view and edit bookings only from their own account. | K34: Fixed
A35: 25 - MyBooking | B35: The page must load within 3 seconds under normal conditions. | C35: Medium | D35: Other | E35: Loged user | F35: 1. Login as a user 2. Open 'My Bookings' and measure its loading time. 3. Repeat the measurement to confirm the issue. | G35: My booking should respond promptly without long waits. | H35: My Bookings page takes an unusually long time to respond. | K35: Duplicate
A36: 26 - Access Control | B36: All /admin routes and actions must be accessible only to users with the Admin role | C36: High | D36: Admin Portal → Access Control | E36: Loged Admin | F36: 1. Log in using an Admin account. 2. Navigate through the available Admin routes. 3. Verify access to the Admin actions. | G36: Only users with the Admin role should be able to access Admin routes and perform Admin actions. | H36: The Admin user can access all routes and actions through the Admin role. | J36: Non-admin access restrictions should be tested separately using a customer account and direct URLs. | K36: Fixed
A37: 27 - Access Control | B37: Identified - Unauthorized users are denied access to Admin actions | C37: High | D37: Admin Portal → Access Control | E37: Non-admin / User | F37: 1. Log in using a non-admin account. 2. Attempt to access an Admin page or perform an Admin-only action. 3. Observe the system response. | G37: Non-admin users must be denied access to Admin routes and actions, regardless of the access method. The system should return a 403 Forbidden response. | H37: The system displays the message '403 — This action is unauthorized.' The unauthorized user cannot access the requested action. | K37: Fixed
A38: 28 - Event Management | B38: Admin can create events with all required fields | C38: Medium | D38: Admin Portal → Event Management | E38: Admin | F38: 1. Log in using an Admin account. 2. Navigate to event creation. 3. Enter the title, description, venue, date/time, capacity, and price. 4. Submit the form. 5. Verify that the event is created successfully. | G38: The Admin should be able to create an event with all required fields, and the event details should be saved correctly. | H38: The event was successfully created with all relevant fields using an Admin account. | K38: Fixed
A39: 29 - Event Management | B39: Admin can create/edit events with all required fields | C39: Medium | D39: Admin Portal → Event Management | E39: Admin | F39: 1. Log in using an Admin account. 2. Navigate to event creation or edit existing event. 3. Enter negative amount of price. 4. Submit the form. 5. Verify that the event is created successfully or not. | G39: The Admin should be able retreve a validation message amount cannot type lessthan 0 | H39: The event was successfully created/ updated with negative amount using an Admin account. | K39: Fixed
A40: 30 - Event Management | B40: Verify Event creation page are displayed with valid details | C40: Medium | D40: Admin Portal → Event Management | E40: Admin | F40: 1. Log in using an Admin account. 2. Open the Create Event page. 3. Enter the title, venue, valid date/time, positive whole-number capacity, and non-negative price. 4. Complete the remaining required fields. 5. Submit the form. 6. Verify that the created event displays all entered details correctly. | G40: The system should accept valid input, save the event, and display all entered details correctly. Invalid values should be rejected with appropriate validation messages. | H40: The event was created successfully, and all relevant details appeared correctly. | K40: Fixed
A41: 31 - Event Management | B41: Event date/time are not updated after editing despite receiving a success notification | C41: High | D41: Admin Portal → Event Management | E41: Admin | F41: 1. Log in using an Admin account. 2. Navigate to event management. 3. Select an existing event date/time to edit. 4. Change the date, and time to valid upcoming values. 5. Save the changes. 6. Observe the update notification. 7. Reopen the event and verify the saved details. | G41: The system should save the date, and time, display a success notification only after a successful update, and show the updated details consistently on the public portal. The event date/time must represent a genuinely upcoming event. | H41: An update notification is displayed, but the original event date/time remain unchanged. | I41: https://drive.google.com/file/d/1izghbltjl_rSTF6I13DGebpB_nJSCHp9/view?usp=sharing | J41: Attach screenshots of the original event details, the update notification, and the event details after attempting to edit. | K41: Open
A42: 32 - Event Management | B42: Event details are not updated after editing despite receiving a success notification | C42: High | D42: Admin Portal → Event Management | E42: Admin | F42: 1. Log in using an Admin account. 2. Navigate to event management. 3. Select an existing event to edit. 4. Change the event title, date, and time to valid upcoming values. 5. Save the changes. 6. Observe the update notification. 7. Reopen the event and verify the saved details. | G42: The system should save the updated title,vanue,amount,date, and time, display a success notification only after a successful update, and show the updated details consistently on the public portal. The event date/time must represent a genuinely upcoming event. | H42: An update notification is displayed, but the original event details remain unchanged. | I42: https://drive.google.com/file/d/1iJpjI3AUpZK4P_0ZcZhKgTJGidErMPV8/view?usp=sharing | J42: Attach screenshots of the original event details, the update notification, and the event details after attempting to edit. | K42: Open
...

Sheet Admin Portal Module
A1: Admin Portal — Module Reference
A2: Use these sub-module names in the Module / Page column when a bug is in the admin area (login as admin@example.com).
A4: Sub-Module | B4: Pages / Routes | C4: Who Can Access | D4: What To Check
A5: Admin Portal → Dashboard | B5: /admin/dashboard | C5: Admin only (role=admin) | D5: Stat tiles match real counts; quick-action links resolve; non-admins redirected away
A6: Admin Portal → Event Management | B6: /admin/events, /admin/events/create, /admin/events/{id}/edit, DELETE /admin/events/{id} | C6: Admin only | D6: Create/edit validation (price, capacity, event_date); delete route's actual middleware vs. the auth group it's declared in; past-dated events
A7: Admin Portal → Booking Management | B7: /admin/bookings | C7: Admin only | D7: Totals match quantity × price; cascade behavior when the related event is deleted
A8: Admin Portal → Access Control | B8: role column on registration, admin middleware group, route list | C8: Should be admin-only; verify it actually is | D8: Try reaching every /admin/* route as a logged-in non-admin and as a guest; compare routes:list middleware to what the UI implies
A9: Admin Portal → QA Bug Reports | B9: /admin/qa-bug-reports | C9: Admin only | D9: Template downloads correctly; only .xlsx/.xls accepted; uploaded reports listed and downloadable

Sheet Severity Guide
A1: Severity Guide
A3: Severity | B3: Definition | C3: Example
A4: Critical | B4: Security vulnerability, data loss/corruption, or a core flow is completely unusable | C4: Any user can register as admin
A5: High | B5: Major functionality broken, no reasonable workaround, affects many users | C5: Wrong total price charged on booking
A6: Medium | B6: Functionality impaired but a workaround exists, or affects a subset of users | C6: Search doesn't return partial matches
A7: Low | B7: Minor functional or UX issue with limited impact | C7: Inconsistent currency formatting
A8: Cosmetic | B8: Visual/text issue with no functional impact | C8: Typo in a success message

Sheet Summary Table
A1: Summary Table (auto-filled from Bug Report sheet)
A3: # | B3: Title | C3: Severity | D3: Module | E3: Status
A4: ='Bug Report'!A14 -> 4 - Event Listing | B4: ='Bug Report'!B14 -> Cards must be evenly aligned in the grid at every screen width (mobile, tablet, desktop) with no overlapping or visually offset cards. | C4: ='Bug Report'!C14 -> Cosmetic | D4: ='Bug Report'!D14 -> Other | E4: ='Bug Report'!K14 -> Open
A5: ='Bug Report'!A15 -> 5 - Event Listing | B5: ='Bug Report'!B15 -> Only events that are genuinely relevant to browse/book should be presented as bookable; past events should be clearly distinguishable from upcoming ones | C5: ='Bug Report'!C15 -> High | D5: ='Bug Report'!D15 -> Public Portal → Event Booking | E5: ='Bug Report'!K15 -> Open
A6: ='Bug Report'!A18 -> 8 - Search | B6: ='Bug Report'!B18 -> Search should match partial and case-insensitive input (e.g. searching “tech” should find “Colombo Tech Summit”). | C6: ='Bug Report'!C18 -> Medium | D6: ='Bug Report'!D18 -> Other | E6: ='Bug Report'!K18 -> Open
A7: ='Bug Report'!A19 -> 9 - Search | B7: ='Bug Report'!B19 -> The search term should remain applied when navigating between pages of results. | C7: ='Bug Report'!C19 -> Medium | D7: ='Bug Report'!D19 -> Other | E7: ='Bug Report'!K19 -> Open
A8: ='Bug Report'!A21 -> 11 - Search | B8: ='Bug Report'!B21 -> Clearing the search field does not automatically refresh the event list | C8: ='Bug Report'!C21 -> Low | D8: ='Bug Report'!D21 -> Other | E8: ='Bug Report'!K21 -> Open
A9: ='Bug Report'!A22 -> 12 - Event details | B9: ='Bug Report'!B22 -> The event details page shows full event information: title, venue, date/time, full description, price, and remaining capacity. | C9: ='Bug Report'!C22 -> Medium | D9: ='Bug Report'!D22 -> Other | E9: ='Bug Report'!K22 -> Open
A10: ='Bug Report'!A23 -> 13 - Event details | B10: ='Bug Report'!B23 -> Logged-in users see a booking form (ticket quantity + “Book Now”); guests see a prompt to log in or register instead. | C10: ='Bug Report'!C23 -> Medium | D10: ='Bug Report'!D23 -> Other | E10: ='Bug Report'!K23 -> Fixed
A11: ='Bug Report'!A24 -> 14 - Booking | B11: ='Bug Report'!B24 -> A logged-in user can book 1 or more tickets for an upcoming event. | C11: ='Bug Report'!C24 -> Medium | D11: ='Bug Report'!D24 -> Public Portal → Event Booking | E11: ='Bug Report'!K24 -> Fixed
A12: ='Bug Report'!A25 -> 15 - Booking | B12: ='Bug Report'!B25 -> The booking quantity must be a positive whole number; zero, negative, decimal, or blank quantities must be rejected with a validation message | C12: ='Bug Report'!C25 -> Medium | D12: ='Bug Report'!D25 -> Public Portal → Event Booking | E12: ='Bug Report'!K25 -> Fixed
A13: ='Bug Report'!A26 -> 16 - Booking | B13: ='Bug Report'!B26 -> Booking quantity exceeds remaining event capacity | C13: ='Bug Report'!C26 -> High | D13: ='Bug Report'!D26 -> Public Portal → Event Booking | E13: ='Bug Report'!K26 -> Open
A14: ='Bug Report'!A27 -> 17 - Booking | B14: ='Bug Report'!B27 -> Incorrect total booking price calculation | C14: ='Bug Report'!C27 -> High | D14: ='Bug Report'!D27 -> Public Portal → Event Booking | E14: ='Bug Report'!K27 -> Open
A15: ='Bug Report'!A28 -> 18 - Booking | B15: ='Bug Report'!B28 -> A single click/submit of Book Now must create exactly one booking - rapid repeated clicks must not create duplicate bookings | C15: ='Bug Report'!C28 -> High | D15: ='Bug Report'!D28 -> Public Portal → Event Booking | E15: ='Bug Report'!K28 -> Fixed
A16: ='Bug Report'!A29 -> 19 - Booking | B16: ='Bug Report'!B29 -> On success, the user is redirected to “My Bookings” with a clear confirmation message, and the new booking appears in the list immediately. | C16: ='Bug Report'!C29 -> Medium | D16: ='Bug Report'!D29 -> Public Portal → Event Booking | E16: ='Bug Report'!K29 -> Open
A17: ='Bug Report'!A30 -> 20 - Booking | B17: ='Bug Report'!B30 -> Booking or My Bookings page responds too slowly | C17: ='Bug Report'!C30 -> Medium | D17: ='Bug Report'!D30 -> Public Portal → Event Booking | E17: ='Bug Report'!K30 -> Open
A18: ='Bug Report'!A31 -> 21 - MyBooking | B18: ='Bug Report'!B31 -> A logged-in user can view all of their own bookings: event, venue, date, quantity, total price, and status | C18: ='Bug Report'!C31 -> Medium | D18: ='Bug Report'!D31 -> Other | E18: ='Bug Report'!K31 -> Fixed
A19: ='Bug Report'!A32 -> 22 - MyBooking | B19: ='Bug Report'!B32 -> Verify that My Bookings summary tiles display total bookings, total tickets, and total amount spent accurately. | C19: ='Bug Report'!C32 -> Medium | D19: ='Bug Report'!D32 -> Other | E19: ='Bug Report'!K32 -> Fixed
... A23: ='Bug Report'!A36 -> 26 - Access Control | B23: ='Bug Report'!B36 -> All /admin routes and actions must be accessible only to users with the Admin role | C23: ='Bug Report'!C36 -> High | D23: ='Bug Report'!D36 -> Admin Portal → Access Control | E23: ='Bug Report'!K36 -> Fixed
A25: Severity | B25: Count
A26: Critical | B26: =COUNTIF('Bug Report'!C14:C36,"Critical") -> 0
A27: High | B27: =COUNTIF('Bug Report'!C14:C36,"High") -> 7
A28: Medium | B28: =COUNTIF('Bug Report'!C14:C36,"Medium") -> 13
A29: Low | B29: =COUNTIF('Bug Report'!C14:C36,"Low") -> 2
A30: Cosmetic | B30: =COUNTIF('Bug Report'!C14:C36,"Cosmetic") -> 1
